Um erro fatal ocorreu:
Traceback (most recent call last):
  File "c:\Users\cmace\OneDrive\Documentos\GitHub\Jogo\Arquivos\Game.py", line 558, in <module>
    main()
    ~~~~^^
  File "c:\Users\cmace\OneDrive\Documentos\GitHub\Jogo\Arquivos\Game.py", line 491, in main
    if gerenciador_eventos: gerenciador_eventos.reativar_eventos_climatico()
                            ^^^^^^^^^^^^^^^^^^^^^^^^^^^^^^^^^^^^^^^^^^^^^^
AttributeError: 'GerenciadorDeEventos' object has no attribute 'reativar_eventos_climatico'. Did you mean: 'reativar_eventos_climaticos'?
